Workbook

Sheet Forside
B2: =Tekstnøgler!C33 -> Resultat
B5: =Hovedresultater!C5 -> Resultat for 0 (År) - Tiltagscase
B6: =Hovedresultater!C6 -> 10.230,61 ton CO₂e
B8: =Tekstnøgler!C3 -> Download af resultater
B10: =Tekstnøgler!C4 -> I dette Excel regneark, kan du finde alle resultater som du kunne se på Klimakompasset for den beregning du har valgt (se navn på beregning ovenfor). Herunder kan du se en liste af de resultater og data, du har adgang til. Da navne på individuelle ark i bunden af Excel-arket ikke ændres, når du vælger mellem dansk og engelsk sprog, er det skrevet ind, hvilke ark de danske titler referer til.
B12: =Tekstnøgler!C5 -> Vælg af sprog | D12: Dansk | E12: =Tekstnøgler!C6 -> <-- klik på cellen
B15: =Tekstnøgler!C7 -> Indholdsfortegnelse
B17: =Tekstnøgler!C8 -> Generelle oplysninger om beregningen | F17: =Tekstnøgler!C587 -> Henviser til ark:
B18: 1. | C18: =Tekstnøgler!C9 -> Forside | F18: =Tekstnøgler!E9 -> Forside
B19: 2. | C19: =Tekstnøgler!C10 -> Stamdata | F19: =Tekstnøgler!E10 -> Stamdata
B20: 3. | C20: =Tekstnøgler!C11 -> Kontaktoplysninger | F20: =Tekstnøgler!E11 -> Kontaktoplysninger
B22: =Tekstnøgler!C12 -> Resultater
B23: 4. | C23: =Tekstnøgler!C13 -> Hovedresultater | F23: =Tekstnøgler!E13 -> Hovedresultater
B24: 5. | C24: =Tekstnøgler!C14 -> Delresultater | F24: =Tekstnøgler!E14 -> Delresultater
B25: 6. | C25: =Tekstnøgler!C15 -> Hovedresultater (GHG) | F25: =Tekstnøgler!E15 -> Hovedresultater (GHG)
B26: 7. | C26: =Tekstnøgler!C16 -> Delresultater (GHG) | F26: =Tekstnøgler!E16 -> Delresultater (GHG)
B27: 8. | C27: =Tekstnøgler!C17 -> E-nøgletal (ESG) | F27: =Tekstnøgler!E17 -> E-nøgletal (ESG)
B28: 9. | C28: =Tekstnøgler!C18 -> Scope 3 kategorier | F28: =Tekstnøgler!E18 -> Scope 3 kategorier
B29: 10. | C29: =Tekstnøgler!C19 -> Største udledningsposter | F29: =Tekstnøgler!E19 -> Største udledningsposter
B31: =Tekstnøgler!C20 -> Fremskrivning & Reduktionsmålsætninger
B32: 11. | C32: =Tekstnøgler!C21 -> Fremskrivning - Hovedresultater | F32: =Tekstnøgler!E21 -> Fremskrivning - Hovedresultater
B33: 12. | C33: =Tekstnøgler!C22 -> Fremskrivning - Delresultater | F33: =Tekstnøgler!E22 -> Fremskrivning - Delresultater
B34: 13. | C34: =Tekstnøgler!C23 -> Reduktionsmålsætninger | F34: =Tekstnøgler!E23 -> Reduktionsmålsætninger
B36: =Tekstnøgler!C24 -> Data
B37: a. | C37: =Tekstnøgler!C25 -> Emissionsfaktorer | F37: =Tekstnøgler!E25 -> Emissionsfaktorer
B38: b. | C38: =Tekstnøgler!C26 -> Egne emissionsfaktorer | F38: =Tekstnøgler!E26 -> Egne emissionsfaktorer
B39: c. | C39: =Tekstnøgler!C27 -> Fremskrevne emissionsfaktorer | F39: =Tekstnøgler!E27 -> Fremskrevne emissionsfaktorer
B40: d. | C40: =Tekstnøgler!C28 -> Data (alle poster) | F40: =Tekstnøgler!E28 -> Data (alle poster)
B41: e. | C41: =Tekstnøgler!C29 -> Data (E-nøgletal) | F41: =Tekstnøgler!E29 -> Data (E-nøgletal)
B43: =Tekstnøgler!C30 -> Til udviklerne | E43: Skjult række
B44: 19. | C44: =Tekstnøgler!C31 -> Til udviklerne | E44: Skjult række
B45: 20. | C45: =Tekstnøgler!C32 -> Tekstnøgler | E45: Skjult række

Sheet Stamdata
B2: =Tekstnøgler!C37 -> Stamdata | I2: =Tekstnøgler!C2 -> <-- Gå til forsiden
B5: =Tekstnøgler!C38 -> Om beregningen
B7: =Tekstnøgler!C39 -> Navn på beregning
B8: 0 (År) - Tiltagscase
B10: =Tekstnøgler!C40 -> Formål med beregningen
B11: =Tekstnøgler!C44 -> 4. Beregn klimaaftrykket for din virksomhed (ingen krav om CVR nr.).
B13: =Tekstnøgler!C45 -> Start dato - Klimaopgørelser laves typisk for et kalenderår
B14: =DATE(2021,1,1) -> 44197 | C14: =IF(OR(ISBLANK(B14),ISTEXT(B14)),Tekstnøgler!C533,"")
B16: =Tekstnøgler!C46 -> Slut dato
B17: =DATE(2021,12,31) -> 44561 | C17: =IF(YEAR(B17)-YEAR(B14)>2,Tekstnøgler!C592,"")
B19: =Tekstnøgler!C47 -> Kommentarer til beregningen
B24: =Tekstnøgler!C48 -> Din virksomhed
B26: =Tekstnøgler!C49 -> CVR
B29: =Tekstnøgler!C50 -> Virksomhedens navn
B30: Testvirksomhed
B34: =Tekstnøgler!C51 -> Virksomhed som beregningen vedrører
B36: =Tekstnøgler!C52 -> Land
B37: Danmark
B39: =Tekstnøgler!C49 -> CVR
B42: =Tekstnøgler!C48 -> Din virksomhed
B43: Tiltagscase - 0
B45: =Tekstnøgler!C53 -> P-nummer
B48: Branche [kommer senere]
B53: =Tekstnøgler!C60 -> Nøgletal
B55: =Tekstnøgler!C61 -> Antal fuldtidsansatte
B56: 50
B58: =Tekstnøgler!C62 -> Nettoomsætning, mio. kr.
B59: 23
B61: =Tekstnøgler!C63 -> Antal m2 bygningsareal
B62: 5000

Sheet Kontaktoplysninger
B2: =Tekstnøgler!C64 -> Kontaktoplysninger | I2: =Tekstnøgler!C2 -> <-- Gå til forsiden
B5: =Tekstnøgler!C65 -> Virksomhedsoplysninger
B7: =Tekstnøgler!C66 -> Virksomhedens e-mailadresse
B11: =Tekstnøgler!C67 -> Kontaktperson
B13: =Tekstnøgler!C68 -> Fornavn
B14: Victor
B16: =Tekstnøgler!C69 -> Efternavn
B17: Skovmand
B19: =Tekstnøgler!C70 -> E-mail
B20: VicSko@erst.dk

Sheet Hovedresultater
C2: =Tekstnøgler!C33 -> Resultat | H2: =Tekstnøgler!C2 -> <-- Gå til forsiden
C5: =Tekstnøgler!C34&" "&Stamdata!B8 -> Resultat for 0 (År) - Tiltagscase
C6: =TEXT(D29, "#.##0,00") & " " & Tekstnøgler!C582 -> 10.230,61 ton CO₂e
C8: =Tekstnøgler!C71 -> Metodevalg | D8: xxxx
C10: =Tekstnøgler!C72 -> Resultaterne baserer sig på en række metodiske valg, der er foretaget i forbindelse med beregningerne. I nedenstående tabel kan du se, hvorvidt Radiative Forcing Index (RFI) er medregnet i forbindelse med udledninger fra flytransport. At medregne (eller korrigere for) RFI betyder, at der er taget højde for, at CO₂e udledt højere oppe i atmosfæren har en større drivhuseffekt end CO₂e udledt ved landjorden. Tabellen viser også, om emissionsfaktoren for el baserer sig på det årlige gennemsnit for sammensætningen af produktionen af el (miljødeklaration), eller om der i emissionsfaktoren korrigeres for virksomheders køb af grønne certifikater, såkaldte oprindelsesgarantier (eldeklaration).
C12: =Tekstnøgler!C73 -> Emissionsfaktor | E12: =Tekstnøgler!C74 -> Metodevalg
C13: =Tekstnøgler!C75 -> Valg af emissionsfaktor for elektricitet | E13: =Tekstnøgler!C79 -> Eldeklaration
C14: =Tekstnøgler!C76 -> Emissionsfaktor for flytransport | E14: =Tekstnøgler!C78 -> Inkluder RFI
C17: =Tekstnøgler!C81 -> Hovedresultater
C19: =Tekstnøgler!C82 -> Virksomhedens samlede CO₂e-udledning er angivet i tabel 1. CO₂e-udledningen er angivet i ton CO₂-ækvivalenter, og tabellen viser udledningen fordelt på de forskellige hovedkategorier. Bemærk, at udenfor scopes ikke medregnes i klimaaftrykket ifølge GHG-protokollen, men kan oplyses særskilt.
C21: =Tekstnøgler!C83 -> Tabel 1: Oversigt over virksomhedens CO₂e-udledninger
C22: =Tekstnøgler!C84 -> Hovedkategori | D22: =Tekstnøgler!C85 -> Udledning i ton CO₂e (scope 1+2+3) | E22: =Tekstnøgler!C86 -> Andel af udledning (scope 1+2+3) | F22: =Tekstnøgler!C110 -> Udledning i ton CO₂e (udenfor scopes)
C24: =Tekstnøgler!C90 -> Energi og processer | D24: =Delresultater!D24 -> 2699.8361 | E24: =IF($D$29 = 0,"",$D24/$D$29) -> 0.2638979 | F24: =Delresultater!F24 -> 137.48754
C25: =Tekstnøgler!C91 -> Indkøb | D25: =Delresultater!D36 -> 6765.5856 | E25: =IF($D$29 = 0,"",$D25/$D$29) -> 0.66130823 | F25: =Delresultater!F36 -> 0
C26: =Tekstnøgler!C92 -> Transport | D26: =Delresultater!D65 -> 765.18681 | E26: =IF($D$29 = 0,"",$D26/$D$29) -> 0.07479387 | F26: =Delresultater!F65 -> 41.952344
C27: =Tekstnøgler!C93 -> Affald og genbrug | D27: =Delresultater!D84 -> 0 | E27: =IF($D$29 = 0,"",$D27/$D$29) -> 0 | F27: =Delresultater!F84 -> -128.21782
C28: =Tekstnøgler!C94 -> Solgte produkter | D28: =Delresultater!D89 -> 0 | E28: =IF($D$29 = 0,"",$D28/$D$29) -> 0 | F28: =Delresultater!F89 -> -111.89732
C29: =Tekstnøgler!C95 -> Total | D29: =SUM(D24:D28) -> 10230.609 | E29: =SUM(E24:E28) -> 1 | F29: =SUM(F24:F28) -> -60.675259
C32: =Tekstnøgler!C96 -> Opsummering af virksomhedens beregnede CO₂e-udledning
C34: =Tekstnøgler!C97 -> Nedenstående figurer opsummerer virksomhedens beregnede CO₂e-udledning. Figur 1 angiver virksomhedens absolutte CO₂e-udledning i ton CO₂e-ækvivalenter fordelt på hovedkategorier. Figur 2 viser den procentuelle fordeling af CO₂e-udledningen fordelt på hovedkategorier.
C36: =Tekstnøgler!C98 -> Figur 1: CO₂e-udledning i ton (scope 1+2+3) fordelt på hovedkategorier | G36: =Tekstnøgler!C99 -> Figur 2: Procentfordeling af CO₂e-udledning (scope 1+2+3) fordelt på hovedkategorier
C57: =Tekstnøgler!C100 -> Figur 3: CO₂e-udledning i ton (udenfor scopes) fordelt på hovedkategorier
C78: =Tekstnøgler!C102 -> Nøgletal
C80: =Tekstnøgler!C103 -> Denne tabel viser beregninger af nøgletal i tilfælde af, at der under Stamdata er indtastet data for hhv. antal fuldtidsansatte i virksomheden, nettoomsætning og areal.
C81: =Tekstnøgler!C104 -> Nøgletalsberegninger | E81: =Tekstnøgler!C105 -> Ton CO₂e
C82: =Tekstnøgler!C106 -> CO₂e pr. ansat | E82: =IF(ISBLANK(Stamdata!B56),"",D29/Stamdata!B56) -> 204.61217
C83: =Tekstnøgler!C107 -> CO₂e pr. mio. kr. nettoomsætning | E83: =IF(ISBLANK(Stamdata!B59),"",D29/Stamdata!B59) -> 444.80907
C84: =Tekstnøgler!C108 -> CO₂e pr. m2 | E84: =IF(ISBLANK(Stamdata!B62),"",D29/Stamdata!B62) -> 2.0461217
C87: =Tekstnøgler!C109 -> Egne bemærkninger

Sheet Delresultater
C2: =Tekstnøgler!C33 -> Resultat | F2: =Tekstnøgler!C2 -> <-- Gå til forsiden
C5: =Hovedresultater!C5 -> Resultat for 0 (År) - Tiltagscase
C6: =Hovedresultater!C6 -> 10.230,61 ton CO₂e
C8: =Tekstnøgler!C71 -> Metodevalg
C10: =Tekstnøgler!C72 -> Resultaterne baserer sig på en række metodiske valg, der er foretaget i forbindelse med beregningerne. I nedenstående tabel kan du se, hvorvidt Radiative Forcing Index (RFI) er medregnet i forbindelse med udledninger fra flytransport. At medregne (eller korrigere for) RFI betyder, at der er taget højde for, at CO₂e udledt højere oppe i atmosfæren har en større drivhuseffekt end CO₂e udledt ved landjorden. Tabellen viser også, om emissionsfaktoren for el baserer sig på det årlige gennemsnit for sammensætningen af produktionen af el (miljødeklaration), eller om der i emissionsfaktoren korrigeres for virksomheders køb af grønne certifikater, såkaldte oprindelsesgarantier (eldeklaration).
C12: =Tekstnøgler!C73 -> Emissionsfaktor | D12: =Tekstnøgler!C74 -> Metodevalg
C13: =Tekstnøgler!C75 -> Valg af emissionsfaktor for elektricitet | D13: =IF(ISBLANK(Hovedresultater!$E13),"",Hovedresultater!$E13) -> Eldeklaration
C14: =Tekstnøgler!C76 -> Emissionsfaktor for flytransport | D14: =IF(ISBLANK(Hovedresultater!$E14),"",Hovedresultater!$E14) -> Inkluder RFI
C17: =Tekstnøgler!C112 -> Delresultater
C19: =Tekstnøgler!C113 -> Her ses en mere detaljeret resultatvisning. Tabellen viser alle underkategorierne, der kan angives data for, den tilhørende udledning i ton CO₂e og underkategoriens samlede andel af de totale udledninger.
C21: =Tekstnøgler!C114 -> Oversigt over CO₂e-udledningen fordelt på hoved- og underkategorier
C22: =Tekstnøgler!C115 -> Hovedkategori | D22: =Tekstnøgler!C85 -> Udledning i ton CO₂e (scope 1+2+3) | E22: =Tekstnøgler!C86 -> Andel af udledning (scope 1+2+3) | F22: =Tekstnøgler!C87 -> Udledning i ton CO₂e (udenfor scopes)
C24: =Tekstnøgler!C90 -> Energi og processer | D24: =D25+D28+D32+D35 -> 2699.8361 | E24: =E25+E28+E32+E35 -> 0.2638979 | F24: =F25+F28+F32+F35 -> 137.48754
C25: =Tekstnøgler!C121 -> Elektricitet | D25: =SUM(D26:D27) -> 2182.8961 | E25: =SUM(E26:E27) -> 0.21336914 | F25: =SUM(F26:F27) -> 129.88681
C26: =Tekstnøgler!C122 -> Forbrug af elektricitet | D26: =SUM('Delresultater (GHG)'!D26:F26) -> 2182.8961 | E26: =IF($D$98 = 0,0,$D26/$D$98) -> 0.21336914 | F26: ='Delresultater (GHG)'!D110 -> 129.88681
C27: =Tekstnøgler!C123 -> Forbrug af elektricitet med egne emissionsfaktorer | D27: =SUM('Delresultater (GHG)'!D27:F27) -> 0 | E27: =IF($D$98 = 0,0,$D27/$D$98) -> 0 | F27: ='Delresultater (GHG)'!D111 -> 0
C28: =Tekstnøgler!C124 -> Varme og procesenergi | D28: =SUM(D29:D31) -> 516.93997 | E28: =SUM(E29:E31) -> 0.05052876 | F28: =SUM(F29:F31) -> 7.6007239
C29: =Tekstnøgler!C125 -> Fjernvarme | D29: =SUM('Delresultater (GHG)'!D29:F29) -> 0 | E29: =IF($D$98 = 0,0,$D29/$D$98) -> 0 | F29: ='Delresultater (GHG)'!D113 -> 0
C30: =Tekstnøgler!C126 -> Brændsler | D30: =SUM('Delresultater (GHG)'!D30:F30) -> 516.93997 | E30: =IF($D$98 = 0,0,$D30/$D$98) -> 0.05052876 | F30: ='Delresultater (GHG)'!D114 -> 7.6007239
C31: =Tekstnøgler!C127 -> Varme og procesenergi med egne emissionsfaktorer | D31: =SUM('Delresultater (GHG)'!D31:F31) -> 0 | E31: =IF($D$98 = 0,0,$D31/$D$98) -> 0 | F31: ='Delresultater (GHG)'!D115 -> 0
C32: =Tekstnøgler!C128 -> Procesudledning | D32: =SUM(D33:D34) -> 0 | E32: =SUM(E33:E34) -> 0 | F32: =SUM(F33:F34) -> 0
C33: =Tekstnøgler!C129 -> Procesudledning | D33: =SUM('Delresultater (GHG)'!D33:F33) -> 0 | E33: =IF($D$98 = 0,0,$D33/$D$98) -> 0 | F33: ='Delresultater (GHG)'!D117 -> 0
C34: =Tekstnøgler!C130 -> Procesudledning med egne emissionsfaktorer | D34: =SUM('Delresultater (GHG)'!D34:F34) -> 0 | E34: =IF($D$98 = 0,0,$D34/$D$98) -> 0 | F34: ='Delresultater (GHG)'!D118 -> 0
C35: =Tekstnøgler!C131 -> Andet udledning ved energi og processer | D35: =SUM('Delresultater (GHG)'!D35:F35) -> 0 | E35: =IF($D$98 = 0,0,$D35/$D$98) -> 0 | F35: ='Delresultater (GHG)'!D119 -> 0
C36: =Tekstnøgler!C91 -> Indkøb | D36: =D37+D51 -> 6765.5856 | E36: =E37+E51 -> 0.66130823 | F36: =F37+F51 -> 0
C37: =Tekstnøgler!C133 -> Primære indkøb af råvarer til produktion | D37: =D38+D43+D48 -> 6765.5856 | E37: =E38+E43+E48 -> 0.66130823 | F37: =F38+F43+F48 -> 0
C38: =Tekstnøgler!C134 -> Materialer (primære indkøb) | D38: =SUM(D39:D42) -> 6760.9302 | E38: =SUM(E39:E42) -> 0.66085318 | F38: =SUM(F39:F42) -> 0
C39: =Tekstnøgler!C135 -> Indkøb af materialer i fysiske enheder | D39: =SUM('Delresultater (GHG)'!D39:F39) -> 6760.9302 | E39: =IF($D$98 = 0,0,$D39/$D$98) -> 0.66085318 | F39: ='Delresultater (GHG)'!D123 -> 0
C40: =Tekstnøgler!C136 -> Indkøb af materialer i monetære enheder (beløb i DKK) | D40: =SUM('Delresultater (GHG)'!D40:F40) -> 0 | E40: =IF($D$98 = 0,0,$D40/$D$98) -> 0 | F40: ='Delresultater (GHG)'!D124 -> 0
C41: =Tekstnøgler!C137 -> Fysiske enheder med egne emissionsfaktorer | D41: =SUM('Delresultater (GHG)'!D41:F41) -> 0 | E41: =IF($D$98 = 0,0,$D41/$D$98) -> 0 | F41: ='Delresultater (GHG)'!D125 -> 0
C42: =Tekstnøgler!C138 -> Monetære enheder (beløb i DKK) med egne emissionsfaktorer | D42: =SUM('Delresultater (GHG)'!D42:F42) -> 0 | E42: =IF($D$98 = 0,0,$D42/$D$98) -> 0 | F42: ='Delresultater (GHG)'!D126 -> 0
C43: =Tekstnøgler!C139 -> Produkter og services (primære indkøb) | D43: =SUM(D44:D47) -> 4.6554366 | E43: =SUM(E44:E47) -> 0.00045504982 | F43: =SUM(F44:F47) -> 0
C44: =Tekstnøgler!C140 -> Indkøb af produkter i fysiske enheder | D44: =SUM('Delresultater (GHG)'!D44:F44) -> 4.6554366 | E44: =IF($D$98 = 0,0,$D44/$D$98) -> 0.00045504982 | F44: ='Delresultater (GHG)'!D128 -> 0
C45: =Tekstnøgler!C141 -> Indkøb af produkter i monetære enheder (beløb i DKK) | D45: =SUM('Delresultater (GHG)'!D45:F45) -> 0 | E45: =IF($D$98 = 0,0,$D45/$D$98) -> 0 | F45: ='Delresultater (GHG)'!D129 -> 0
C46: =Tekstnøgler!C142 -> Fysiske enheder med egne emissionsfaktorer | D46: =SUM('Delresultater (GHG)'!D46:F46) -> 0 | E46: =IF($D$98 = 0,0,$D46/$D$98) -> 0 | F46: ='Delresultater (GHG)'!D130 -> 0
C47: =Tekstnøgler!C143 -> Monetære enheder (beløb i DKK) med egne emissionsfaktorer | D47: =SUM('Delresultater (GHG)'!D47:F47) -> 0 | E47: =IF($D$98 = 0,0,$D47/$D$98) -> 0 | F47: ='Delresultater (GHG)'!D131 -> 0
C48: =Tekstnøgler!C144 -> Andet udledning ved primære indkøb | D48: =SUM(D49:D50) -> 0 | E48: =SUM(E49:E50) -> 0 | F48: =SUM(F49:F50) -> 0
C49: =Tekstnøgler!C145 -> Fysiske enheder med egne emissionsfaktorer | D49: =SUM('Delresultater (GHG)'!D49:F49) -> 0 | E49: =IF($D$98 = 0,0,$D49/$D$98) -> 0 | F49: ='Delresultater (GHG)'!D133 -> 0
C50: =Tekstnøgler!C146 -> Monetære enheder (beløb i DKK) med egne emissionsfaktorer | D50: =SUM('Delresultater (GHG)'!D50:F50) -> 0 | E50: =IF($D$98 = 0,0,$D50/$D$98) -> 0 | F50: ='Delresultater (GHG)'!D134 -> 0
C51: =Tekstnøgler!C147 -> Sekundære indkøb af hjælpematerialer og serviceydelser | D51: =D52+D57+D62 -> 0 | E51: =E52+E57+E62 -> 0 | F51: =F52+F57+F62 -> 0
...

Sheet Hovedresultater (GHG)
C2: =Tekstnøgler!C196 -> Resultat (GHG) | I2: =Tekstnøgler!C2 -> <-- Gå til forsiden
C5: =Hovedresultater!C5 -> Resultat for 0 (År) - Tiltagscase
C6: =Hovedresultater!C6 -> 10.230,61 ton CO₂e
C8: =Tekstnøgler!C71 -> Metodevalg
C10: =Tekstnøgler!C72 -> Resultaterne baserer sig på en række metodiske valg, der er foretaget i forbindelse med beregningerne. I nedenstående tabel kan du se, hvorvidt Radiative Forcing Index (RFI) er medregnet i forbindelse med udledninger fra flytransport. At medregne (eller korrigere for) RFI betyder, at der er taget højde for, at CO₂e udledt højere oppe i atmosfæren har en større drivhuseffekt end CO₂e udledt ved landjorden. Tabellen viser også, om emissionsfaktoren for el baserer sig på det årlige gennemsnit for sammensætningen af produktionen af el (miljødeklaration), eller om der i emissionsfaktoren korrigeres for virksomheders køb af grønne certifikater, såkaldte oprindelsesgarantier (eldeklaration).
C12: =Tekstnøgler!C73 -> Emissionsfaktor | E12: =Tekstnøgler!C74 -> Metodevalg
C13: =Tekstnøgler!C75 -> Valg af emissionsfaktor for elektricitet | E13: =IF(ISBLANK(Hovedresultater!$E13),"",Hovedresultater!$E13) -> Eldeklaration
C14: =Tekstnøgler!C76 -> Emissionsfaktor for flytransport | E14: =IF(ISBLANK(Hovedresultater!$E14),"",Hovedresultater!$E14) -> Inkluder RFI
C17: =Tekstnøgler!C197 -> Hovedresultater (GHG)
C19: =Tekstnøgler!C198 -> Virksomhedens samlede CO₂e-udledning er angivet i tabel 1. CO₂e-udledningen er angivet i ton CO₂-ækvivalenter, og tabellen viser udledningen fordelt på scope 1, 2 og 3 jf. GHG-protokollen. Udledningen udenfor scopes medregnes ikke jf. GHG-protokollen og indgår derfor ikke i totalen.
C20: =Tekstnøgler!C199 -> Tabel 1: Oversigt over virksomhedens samlede CO₂e-udledninger
C21: =Tekstnøgler!C200 -> Scope | D21: =Tekstnøgler!C201 -> Ton CO₂e | E21: =Tekstnøgler!C202 -> Andel af udledning
C22: =Tekstnøgler!C203 -> Scope 1 | D22: ='Delresultater (GHG)'!D98 -> 443.36484 | E22: =IF(ISBLANK($D22),,$D22/$D$25) -> 0.043337094
C23: =Tekstnøgler!C204 -> Scope 2 | D23: ='Delresultater (GHG)'!E98 -> 1851.795 | E23: =IF(ISBLANK($D23),,$D23/$D$25) -> 0.18100536
C24: =Tekstnøgler!C205 -> Scope 3 | D24: ='Delresultater (GHG)'!F98 -> 7935.4487 | E24: =IF(ISBLANK($D24),,$D24/$D$25) -> 0.77565754
C25: =Tekstnøgler!C95 -> Total | D25: =SUM(D22:D24) -> 10230.609 | E25: =SUM(E22:E24) -> 1
C28: =Tekstnøgler!C207 -> Opsummering af virksomhedens beregnede CO2e-udledning
C30: =Tekstnøgler!C208 -> Nedenstående figurer viser grafiske fremstillinger af virksomhedens beregnede CO₂e-udledning. Figur 1 angiver virksomhedens absolutte udledning i ton CO₂-ækvivalenter fordelt på scope 1, 2, og 3. Figur 2 viser den procentuelle fordeling af CO₂e-udledningen fordelt på scope 1, 2 og 3.
C31: =Tekstnøgler!C209 -> Figur 1: Virksomhedens samlede CO₂e-udledning i ton fordelt på scopes | H31: =Tekstnøgler!C210 -> Figur 2: Procentfordeling af CO₂e-udledning fordelt på scopes
C50: =Tekstnøgler!C211 -> Nøgletal
C52: =Tekstnøgler!C212 -> Denne tabel viser beregninger af nøgletal i tilfælde af, at der under Stamdata er indtastet data for hhv. antal fuldtidsansatte i virksomheden, nettoomsætning og areal.
C54: =Tekstnøgler!C213 -> Nøgletalsberegninger | E54: =Tekstnøgler!C214 -> Ton CO₂e
C55: =Tekstnøgler!C215 -> CO₂e pr. ansat | E55: =IF(ISBLANK(Hovedresultater!E82),"",Hovedresultater!E82) -> 204.61217
C56: =Tekstnøgler!C216 -> CO₂e pr. mio. kr. nettoomsætning | E56: =IF(ISBLANK(Hovedresultater!E83),"",Hovedresultater!E83) -> 444.80907
C57: =Tekstnøgler!C217 -> CO₂e pr. m2 | E57: =IF(ISBLANK(Hovedresultater!E84),"",Hovedresultater!E84) -> 2.0461217
C60: =Tekstnøgler!C218 -> Udenfor scopes resultater
C62: =Tekstnøgler!C219 -> I en række tilfælde vil Klimakompasset vise nogle resultater i 'udenfor scope'. Dette gælder fx biogen CO₂e-udledning fra forbrænding af biobrændsel. Dette gælder også evt. undgåede udledninger som fx undgået produktion af nye materialer ved at sende affald til genanvendelse. Jf. GHG-protokollen medregnes disse udledninger ikke under scope 1, 2 og 3 og indgår derfor ikke i totalen.
C64: =Tekstnøgler!C220 -> Udenfor scopes resultater
C65: =Tekstnøgler!C221 -> Scope | D65: =Tekstnøgler!C222 -> Ton CO₂e | E65: =Tekstnøgler!C223 -> Andel af udledning
C66: =Tekstnøgler!C224 -> Udenfor scope | D66: ='Delresultater (GHG)'!D182 -> -60.675259 | E66: =D66/D25 -> -0.0059307576
C69: =Tekstnøgler!C109 -> Egne bemærkninger
C71: =IF(ISTEXT(Hovedresultater!C89),Hovedresultater!C89,"")

Sheet Delresultater (GHG)
C2: =Tekstnøgler!C196 -> Resultat (GHG) | F2: =Tekstnøgler!C2 -> <-- Gå til forsiden
C5: =Hovedresultater!C5 -> Resultat for 0 (År) - Tiltagscase
C6: =Hovedresultater!C6 -> 10.230,61 ton CO₂e
C8: =Tekstnøgler!C71 -> Metodevalg
C10: =Tekstnøgler!C72 -> Resultaterne baserer sig på en række metodiske valg, der er foretaget i forbindelse med beregningerne. I nedenstående tabel kan du se, hvorvidt Radiative Forcing Index (RFI) er medregnet i forbindelse med udledninger fra flytransport. At medregne (eller korrigere for) RFI betyder, at der er taget højde for, at CO₂e udledt højere oppe i atmosfæren har en større drivhuseffekt end CO₂e udledt ved landjorden. Tabellen viser også, om emissionsfaktoren for el baserer sig på det årlige gennemsnit for sammensætningen af produktionen af el (miljødeklaration), eller om der i emissionsfaktoren korrigeres for virksomheders køb af grønne certifikater, såkaldte oprindelsesgarantier (eldeklaration).
C12: =Tekstnøgler!C73 -> Emissionsfaktor | D12: =Tekstnøgler!C74 -> Metodevalg
C13: =Tekstnøgler!C75 -> Valg af emissionsfaktor for elektricitet | D13: =IF(ISBLANK(Hovedresultater!$E13),"",Hovedresultater!$E13) -> Eldeklaration
C14: =Tekstnøgler!C76 -> Emissionsfaktor for flytransport | D14: =IF(ISBLANK(Hovedresultater!$E14),"",Hovedresultater!$E14) -> Inkluder RFI
C17: =Tekstnøgler!C227 -> Delresultater (GHG)
C19: =Tekstnøgler!C228 -> Her ses en mere detaljeret resultatvisning. Tabellen viser alle underkategorierne, der kan angives data for, den tilhørende udledning i ton CO₂e og underkategoriens samlede andel af de totale udledninger.
C21: =Tekstnøgler!C226 -> Oversigt over CO₂e-udledningen fordelt på hoved- og underkategorier
C22: =Tekstnøgler!C115 -> Hovedkategori | D22: =Tekstnøgler!C203 -> Scope 1 | E22: =Tekstnøgler!C204 -> Scope 2 | F22: =Tekstnøgler!C205 -> Scope 3 | G22: =Tekstnøgler!C230 -> Samlede CO₂e udledning i ton (scope 1+2+3)
D23: =Tekstnøgler!C229 -> (ton CO₂e) | E23: =Tekstnøgler!C229 -> (ton CO₂e) | F23: =Tekstnøgler!C229 -> (ton CO₂e) | G23: =Tekstnøgler!C229 -> (ton CO₂e)
C24: =Tekstnøgler!C90 -> Energi og processer | D24: =D25+D28+D32+D35 -> 435.44571 | E24: =E25+E28+E32+E35 -> 1851.795 | F24: =F25+F28+F32+F35 -> 412.59541 | G24: =G25+G28+G32+G35 -> 2699.8361
C25: =Tekstnøgler!C121 -> Elektricitet | D25: =SUM(D26:D27) -> 0 | E25: =SUM(E26:E27) -> 1851.795 | F25: =SUM(F26:F27) -> 331.10115 | G25: =SUM(G26:G27) -> 2182.8961
C26: =Tekstnøgler!C122 -> Forbrug af elektricitet | D26: 0 | E26: 1851.795 | F26: 331.10115 | G26: =D26+E26+F26 -> 2182.8961
C27: =Tekstnøgler!C123 -> Forbrug af elektricitet med egne emissionsfaktorer | D27: 0 | E27: 0 | F27: 0 | G27: =D27+E27+F27 -> 0
C28: =Tekstnøgler!C124 -> Varme og procesenergi | D28: =SUM(D29:D31) -> 435.44571 | E28: =SUM(E29:E31) -> 0 | F28: =SUM(F29:F31) -> 81.494262 | G28: =SUM(G29:G31) -> 516.93997
C29: =Tekstnøgler!C125 -> Fjernvarme | D29: 0 | E29: 0 | F29: 0 | G29: =D29+E29+F29 -> 0
C30: =Tekstnøgler!C126 -> Brændsler | D30: 435.44571 | E30: 0 | F30: 81.494262 | G30: =D30+E30+F30 -> 516.93997
C31: =Tekstnøgler!C127 -> Varme og procesenergi med egne emissionsfaktorer | D31: 0 | E31: 0 | F31: 0 | G31: =D31+E31+F31 -> 0
C32: =Tekstnøgler!C128 -> Procesudledning | D32: =SUM(D33:D34) -> 0 | E32: =SUM(E33:E34) -> 0 | F32: =SUM(F33:F34) -> 0 | G32: =SUM(G33:G34) -> 0
C33: =Tekstnøgler!C129 -> Procesudledning | D33: 0 | E33: 0 | F33: 0 | G33: =D33+E33+F33 -> 0
C34: =Tekstnøgler!C130 -> Procesudledning med egne emissionsfaktorer | D34: 0 | E34: 0 | F34: 0 | G34: =D34+E34+F34 -> 0
C35: =Tekstnøgler!C131 -> Andet udledning ved energi og processer | D35: 0 | E35: 0 | F35: 0 | G35: =D35+E35+F35 -> 0
C36: =Tekstnøgler!C91 -> Indkøb | D36: =D37+D51 -> 0 | E36: =E37+E51 -> 0 | F36: =F37+F51 -> 6765.5856 | G36: =G37+G51 -> 6765.5856
C37: =Tekstnøgler!C133 -> Primære indkøb af råvarer til produktion | D37: =D38+D43+D48 -> 0 | E37: =E38+E43+E48 -> 0 | F37: =F38+F43+F48 -> 6765.5856 | G37: =G38+G43+G48 -> 6765.5856
C38: =Tekstnøgler!C134 -> Materialer (primære indkøb) | D38: =SUM(D39:D42) -> 0 | E38: =SUM(E39:E42) -> 0 | F38: =SUM(F39:F42) -> 6760.9302 | G38: =SUM(G39:G42) -> 6760.9302
C39: =Tekstnøgler!C135 -> Indkøb af materialer i fysiske enheder | D39: 0 | E39: 0 | F39: 6760.9302 | G39: =D39+E39+F39 -> 6760.9302
C40: =Tekstnøgler!C136 -> Indkøb af materialer i monetære enheder (beløb i DKK) | D40: 0 | E40: 0 | F40: 0 | G40: =D40+E40+F40 -> 0
C41: =Tekstnøgler!C137 -> Fysiske enheder med egne emissionsfaktorer | D41: 0 | E41: 0 | F41: 0 | G41: =D41+E41+F41 -> 0
C42: =Tekstnøgler!C138 -> Monetære enheder (beløb i DKK) med egne emissionsfaktorer | D42: 0 | E42: 0 | F42: 0 | G42: =D42+E42+F42 -> 0
C43: =Tekstnøgler!C139 -> Produkter og services (primære indkøb) | D43: =SUM(D44:D47) -> 0 | E43: =SUM(E44:E47) -> 0 | F43: =SUM(F44:F47) -> 4.6554366 | G43: =SUM(G44:G47) -> 4.6554366
C44: =Tekstnøgler!C140 -> Indkøb af produkter i fysiske enheder | D44: 0 | E44: 0 | F44: 4.6554366 | G44: =D44+E44+F44 -> 4.6554366
C45: =Tekstnøgler!C141 -> Indkøb af produkter i monetære enheder (beløb i DKK) | D45: 0 | E45: 0 | F45: 0 | G45: =D45+E45+F45 -> 0
C46: =Tekstnøgler!C142 -> Fysiske enheder med egne emissionsfaktorer | D46: 0 | E46: 0 | F46: 0 | G46: =D46+E46+F46 -> 0
C47: =Tekstnøgler!C143 -> Monetære enheder (beløb i DKK) med egne emissionsfaktorer | D47: 0 | E47: 0 | F47: 0 | G47: =D47+E47+F47 -> 0
C48: =Tekstnøgler!C144 -> Andet udledning ved primære indkøb | D48: =SUM(D49:D50) -> 0 | E48: =SUM(E49:E50) -> 0 | F48: =SUM(F49:F50) -> 0 | G48: =SUM(G49:G50) -> 0
C49: =Tekstnøgler!C145 -> Fysiske enheder med egne emissionsfaktorer | D49: 0 | E49: 0 | F49: 0 | G49: =D49+E49+F49 -> 0
C50: =Tekstnøgler!C146 -> Monetære enheder (beløb i DKK) med egne emissionsfaktorer | D50: 0 | E50: 0 | F50: 0 | G50: =D50+E50+F50 -> 0
...

Sheet E-nøgletal (ESG)
C2: =Tekstnøgler!C33 -> Resultat | E2: =Tekstnøgler!C2 -> <-- Gå til forsiden
C5: =Hovedresultater!C5 -> Resultat for 0 (År) - Tiltagscase
C6: =Hovedresultater!C6 -> 10.230,61 ton CO₂e
C8: =Tekstnøgler!C71 -> Metodevalg
C10: =Tekstnøgler!C72 -> Resultaterne baserer sig på en række metodiske valg, der er foretaget i forbindelse med beregningerne. I nedenstående tabel kan du se, hvorvidt Radiative Forcing Index (RFI) er medregnet i forbindelse med udledninger fra flytransport. At medregne (eller korrigere for) RFI betyder, at der er taget højde for, at CO₂e udledt højere oppe i atmosfæren har en større drivhuseffekt end CO₂e udledt ved landjorden. Tabellen viser også, om emissionsfaktoren for el baserer sig på det årlige gennemsnit for sammensætningen af produktionen af el (miljødeklaration), eller om der i emissionsfaktoren korrigeres for virksomheders køb af grønne certifikater, såkaldte oprindelsesgarantier (eldeklaration).
C12: =Tekstnøgler!C73 -> Emissionsfaktor | D12: =Tekstnøgler!C74 -> Metodevalg
C13: =Tekstnøgler!C75 -> Valg af emissionsfaktor for elektricitet | D13: =IF(ISBLANK(Hovedresultater!$E13),"",Hovedresultater!$E13) -> Eldeklaration
C14: =Tekstnøgler!C76 -> Emissionsfaktor for flytransport | D14: =IF(ISBLANK(Hovedresultater!$E14),"",Hovedresultater!$E14) -> Inkluder RFI
C17: =Tekstnøgler!C238 -> E-nøgletal (ESG)
C19: =Tekstnøgler!C241 -> ESG står for Environment, Social og Governance og dækker over ikke-finansielle nøgletal, som kan indgå i din virksomheds opgørelse, dokumentation og rapportering af bæredygtighed ift. miljø- og klimamæssige forhold, sociale forhold samt god selskabsledelse. En række vejledende nøgletal under "E" kan beregnes med Klimakompasset, når du udarbejder dit klimaaftryk. Nøgletallene er kun vejledende og kan ikke bruges til at verificere din ESG-rapport. Læs mere om ESG på Virksomhedsguiden.
C21: =Tekstnøgler!C239 -> E-nøgletal
C23: =Tekstnøgler!C242 -> CO₂e-udledning | E23: =Tekstnøgler!C245 -> Resultat | G23: =Tekstnøgler!C244 -> Enhed
C24: =Tekstnøgler!C247 -> CO₂e-udledning inden for scope 1 | E24: ='Delresultater (GHG)'!D98 -> 443.36484 | G24: =Tekstnøgler!C263 -> Ton CO₂e
C25: =Tekstnøgler!C248 -> CO₂e-udledning inden for scope 2 | E25: ='Delresultater (GHG)'!E98 -> 1851.795 | G25: =Tekstnøgler!C263 -> Ton CO₂e
C26: =Tekstnøgler!C250 -> Samlet CO₂e-udledning (Scope 1 og 2) | E26: 2295.1598 | G26: =Tekstnøgler!C263 -> Ton CO₂e
C27: =Tekstnøgler!C253 -> CO₂ intensitet (CO₂e-udledning for scope 1 og 2 ift. nettoomsætning) | E27: =IF(AND(ISNUMBER(E66),ISNUMBER(E26),E66>0),E26/E66,Tekstnøgler!C269) -> 99.789558 | G27: =Tekstnøgler!C264 -> Ton CO₂e / mio. DKK
C28: =Tekstnøgler!C249 -> CO₂e-udledning inden for scope 3 | E28: ='Delresultater (GHG)'!F98 -> 7935.4487 | G28: =Tekstnøgler!C263 -> Ton CO₂e
C29: =Tekstnøgler!C251 -> Samlet CO₂e-udledning (Scope 1, 2 og 3) | E29: ='Delresultater (GHG)'!G98 -> 10230.609 | G29: =Tekstnøgler!C263 -> Ton CO₂e
C30: =Tekstnøgler!C252 -> CO₂ intensitet (Samlet CO₂e-udledning ift. nettoomsætning) | E30: =IF(AND(ISNUMBER(E66),ISNUMBER(E29),E66>0),E29/E66,Tekstnøgler!C269) -> 444.80907 | G30: =Tekstnøgler!C264 -> Ton CO₂e / mio. DKK
C32: =Tekstnøgler!C602 -> Her ses din virksomheds samlede forbrug af elektricitet, og heraf hvad som kommer fra vedvarende energikilder. Bemærk, at den nukleare energiandel er medregnet under vedvarende elektricitet. Det skyldes, at den nukleare andel ikke udleder CO₂e.
C34: =Tekstnøgler!C284 -> Energiforbrug | D34: =Tekstnøgler!C285 -> Vedvarende | E34: =Tekstnøgler!C286 -> Ikke vedvarende | F34: =Tekstnøgler!C287 -> Total | G34: =Tekstnøgler!C244 -> Enhed
C35: =Tekstnøgler!C293 -> Elektricitet | D35: 1819.6129 | E35: 2680.3871 | F35: =IF(OR(ISNUMBER(D35),ISNUMBER(E35)),SUM(D35:E35),Tekstnøgler!$C$269) -> 4500 | G35: =Tekstnøgler!C289 -> MWh
C36: =Tekstnøgler!C294 -> Brændsler | D36: 48.993722 | E36: 1940.8372 | F36: =IF(OR(ISNUMBER(D36),ISNUMBER(E36)),SUM(D36:E36),Tekstnøgler!$C$269) -> 1989.831 | G36: =Tekstnøgler!C289 -> MWh
C37: =Tekstnøgler!C295 -> Fjernvarme | D37: =Tekstnøgler!C269 -> (ikke angivet) | E37: =Tekstnøgler!C269 -> (ikke angivet) | F37: =IF(OR(ISNUMBER(D37),ISNUMBER(E37)),SUM(D37:E37),Tekstnøgler!$C$269) -> (ikke angivet) | G37: =Tekstnøgler!C289 -> MWh
C38: =Tekstnøgler!C287 -> Total | D38: =IF(OR(ISNUMBER(D35),ISNUMBER(D36),ISNUMBER(D37)),SUM(D35:D37),Tekstnøgler!$C$269) -> 1868.6067 | E38: =IF(OR(ISNUMBER(E35),ISNUMBER(E36),ISNUMBER(E37)),SUM(E35:E37),Tekstnøgler!$C$269) -> 4621.2243 | F38: =IF(OR(ISNUMBER(F35),ISNUMBER(F36),ISNUMBER(F37)),SUM(F35:F37),Tekstnøgler!$C$269) -> 6489.831 | G38: =Tekstnøgler!C289 -> MWh
C41: =Tekstnøgler!C240 -> Andre nøgletal
C43: =Tekstnøgler!C600 -> Her ses din virksomheds samlede energiforbrug, samt hvor stor andel af energiforbruget der kommer fra hhv. fossile kilder (såsom olie og gas), nukleare kilder (atomkraft) og vedvarende kilder (fx solcelle-energi).
C45: =Tekstnøgler!C282 -> Energiforbrug fordelt på kilder | E45: =Tekstnøgler!C245 -> Resultat | F45: =Tekstnøgler!C244 -> Enhed | G45: =Tekstnøgler!C246 -> Andel
C46: =Tekstnøgler!C254 -> Energiforbrug: Fossile kilder | E46: 4621.2243 | F46: =Tekstnøgler!C289 -> MWh | G46: =IF(AND(ISNUMBER(E46),ISNUMBER($E$49),$E$49<>0),E46/$E$49,Tekstnøgler!$C$269) -> 0.7120716
C47: =Tekstnøgler!C255 -> Energiforbrug: Nukleare kilder | E47: 1389.2904 | F47: =Tekstnøgler!C289 -> MWh | G47: =IF(AND(ISNUMBER(E47),ISNUMBER($E$49),$E$49<>0),E47/$E$49,Tekstnøgler!$C$269) -> 0.21407189
C48: =Tekstnøgler!C256 -> Energiforbrug: Vedvarende kilder | E48: 479.31625 | F48: =Tekstnøgler!C289 -> MWh | G48: =IF(AND(ISNUMBER(E48),ISNUMBER($E$49),$E$49<>0),E48/$E$49,Tekstnøgler!$C$269) -> 0.073856508
C49: =Tekstnøgler!C257 -> Samlet energiforbrug | E49: =IF(OR(ISNUMBER(E46),ISNUMBER(E47),ISNUMBER(E48)),SUM(E46:E48),Tekstnøgler!$C$269) -> 6489.831 | F49: =Tekstnøgler!C289 -> MWh | G49: =IF(ISNUMBER(E49),"100,00%",Tekstnøgler!$C$269) -> 100,00%
C51: =Tekstnøgler!C601 -> Her ses din virksomheds samlede vandforbrug, og hvad vandintensiteten er. Du kan også se virksomhedens samlede mængde affald, heraf hvor stor andel som er farligt affald og hvor stor andel som bliver sendt til genanvendelse eller genbrug.
C53: =Tekstnøgler!C283 -> Vand og affald | E53: =Tekstnøgler!C245 -> Resultat | G53: =Tekstnøgler!C244 -> Enhed
C54: =Tekstnøgler!C260 -> Samlet vandforbrug | E54: 2000 | G54: =Tekstnøgler!C290 -> m3
C55: =Tekstnøgler!C292 -> Samlet mængde affald | E55: 360 | G55: =Tekstnøgler!C280 -> Ton
C56: =Tekstnøgler!C261 -> Andel af farligt affald (Mængde af farligt affald ift. total mængde affald) | E56: =IF(AND(ISNUMBER(E68),ISNUMBER(E69)),E69/E68,Tekstnøgler!C269) -> (ikke angivet) | G56: =Tekstnøgler!C267 -> Pct. (%)
C57: =Tekstnøgler!C262 -> Andel affald sendt til genanvendelse og genbrug (Mængde af genanvendt affald ift. total mængde affald) | E57: =IF(AND(ISNUMBER(E68),ISNUMBER(E70)),E70/E68,Tekstnøgler!C269) -> 0.72222222 | G57: =Tekstnøgler!C267 -> Pct. (%)
C60: =Tekstnøgler!C270 -> Anvendte værdier i beregning af E-nøgletal (ESG)
C62: =Tekstnøgler!C271 -> I følgende tabel kan du se de værdier, der er anvendt i beregningen af E-nøgletallene præsenteret i tabellen ovenfor
...

Sheet Scope 3 kategorier
C2: =Tekstnøgler!C33 -> Resultat | E2: =Tekstnøgler!C2 -> <-- Gå til forsiden
C5: =Hovedresultater!C5 -> Resultat for 0 (År) - Tiltagscase
C6: =Hovedresultater!C6 -> 10.230,61 ton CO₂e
C8: =Tekstnøgler!C71 -> Metodevalg
C10: =Tekstnøgler!C72 -> Resultaterne baserer sig på en række metodiske valg, der er foretaget i forbindelse med beregningerne. I nedenstående tabel kan du se, hvorvidt Radiative Forcing Index (RFI) er medregnet i forbindelse med udledninger fra flytransport. At medregne (eller korrigere for) RFI betyder, at der er taget højde for, at CO₂e udledt højere oppe i atmosfæren har en større drivhuseffekt end CO₂e udledt ved landjorden. Tabellen viser også, om emissionsfaktoren for el baserer sig på det årlige gennemsnit for sammensætningen af produktionen af el (miljødeklaration), eller om der i emissionsfaktoren korrigeres for virksomheders køb af grønne certifikater, såkaldte oprindelsesgarantier (eldeklaration).
C12: =Tekstnøgler!C73 -> Emissionsfaktor | D12: =Tekstnøgler!C74 -> Metodevalg
C13: =Tekstnøgler!C75 -> Valg af emissionsfaktor for elektricitet | D13: =IF(ISBLANK(Hovedresultater!$E13),"",Hovedresultater!$E13) -> Eldeklaration
C14: =Tekstnøgler!C76 -> Emissionsfaktor for flytransport | D14: =IF(ISBLANK(Hovedresultater!$E14),"",Hovedresultater!$E14) -> Inkluder RFI
C17: =Tekstnøgler!C299 -> Scope 3 kategorier
C19: =Tekstnøgler!C300 -> GHG protokollen opdeler scope 3 udledning i 15 kategorier for hhv. opstrømsudledninger, der opstår tidligere i virksomhedens værdikæde (fx indkøb af varer og services eller fragt til virksomheden) og for nedstrømsudledninger, der opstår senere i virksomhedens værdikæde (fx brug og bortskaffelse af virksomhedens produkter). Bemærk, at kategori 14 (franchises) og kategori 15 (investeringer) ikke er medtaget her, da de ligger udover Klimakompassets anvendelse. Vær opmærksom på, at der i visningen af dine scope 3 udledninger er mulighed for at vise dit forbrug af elektricitet opgjort enten ved brug af metoderne ”eldeklaration” eller ”miljødeklaration”. GHG-protokollen anbefaler, at du laver to ens opgørelser, hvor den eneste forskel er, hvilken deklaration der klikkes af i Klimakompasset. Virksomhedens CO₂e-udledninger inden for de forskellige scope 3 kategorier er vist i diagrammet samt i tabellen nedenfor.
C21: =Tekstnøgler!C301 -> SCOPE 3 KATEGORIER I TON CO₂e
C22: =Tekstnøgler!C302 -> Kategori | D22: =Tekstnøgler!C303 -> Opstrøms | E22: =Tekstnøgler!C304 -> Nedstrøms
C23: =Tekstnøgler!C305 -> 1. Indkøb af varer og tjenesteydelser | D23: 6765.5856
C24: =Tekstnøgler!C306 -> 2. Anlægsaktiver
C25: =Tekstnøgler!C307 -> 3. Brændsels- og energirelaterede aktiviteter | D25: 414.72539
C26: =Tekstnøgler!C308 -> 4. Opstrømstransport og distribution | D26: 204.96
C27: =Tekstnøgler!C309 -> 5. Affald fra drift | D27: 0
C28: =Tekstnøgler!C310 -> 6. Forretningsrejser
C29: =Tekstnøgler!C311 -> 7. Medarbejderpendling | D29: 3.6176839
C30: =Tekstnøgler!C312 -> 8. Opstrøms leasede aktiver
C31: =Tekstnøgler!C313 -> 9. Nedstrømstransport og distribution | E31: 546.56
C32: =Tekstnøgler!C314 -> 10. Forarbejdning af solgte produkter
C33: =Tekstnøgler!C315 -> 11. Brug af solgte produkter
C34: =Tekstnøgler!C316 -> 12. Behandling af solgte produkter efter endt levetid | E34: 0
C35: =Tekstnøgler!C317 -> 13. Nedstrøms leasede aktiver
C36: =Tekstnøgler!C318 -> Samlede CO₂e udledninger fordelt på opstrøm og nedstrøm (ton) | D36: =SUM(D23:D30) -> 7388.8887 | E36: =SUM(E31:E35) -> 546.56
C37: =Tekstnøgler!C319 -> Samlet CO₂e udledning i alt (ton) | E37: =D36+E36 -> 7935.4487 | F37: =IF(E37>'Delresultater (GHG)'!F98,Tekstnøgler!C538,"")
C39: =Tekstnøgler!C320 -> Opsummering af virksomhedens beregnede CO₂e-udledning
C41: =Tekstnøgler!C321 -> Nedenstående figur angiver virksomhedens opgjorte udledning i ton CO₂-ækvivalenter fordelt på scope 3 kategorier.
C42: =Tekstnøgler!C322 -> Figur 1: CO₂e udledning fordelt på scope 3 kategorier (ton)

Sheet Største udledningsposter
C2: =Tekstnøgler!C33 -> Resultat | E2: =Tekstnøgler!C2 -> <-- Gå til forsiden
C5: =Hovedresultater!C5 -> Resultat for 0 (År) - Tiltagscase
C6: =Hovedresultater!C6 -> 10.230,61 ton CO₂e
C8: =Tekstnøgler!C71 -> Metodevalg
C10: =Tekstnøgler!C72 -> Resultaterne baserer sig på en række metodiske valg, der er foretaget i forbindelse med beregningerne. I nedenstående tabel kan du se, hvorvidt Radiative Forcing Index (RFI) er medregnet i forbindelse med udledninger fra flytransport. At medregne (eller korrigere for) RFI betyder, at der er taget højde for, at CO₂e udledt højere oppe i atmosfæren har en større drivhuseffekt end CO₂e udledt ved landjorden. Tabellen viser også, om emissionsfaktoren for el baserer sig på det årlige gennemsnit for sammensætningen af produktionen af el (miljødeklaration), eller om der i emissionsfaktoren korrigeres for virksomheders køb af grønne certifikater, såkaldte oprindelsesgarantier (eldeklaration).
C12: =Tekstnøgler!C73 -> Emissionsfaktor | D12: =Tekstnøgler!C74 -> Metodevalg
C13: =Tekstnøgler!C75 -> Valg af emissionsfaktor for elektricitet | D13: =IF(ISBLANK(Hovedresultater!$E13),"",Hovedresultater!$E13) -> Eldeklaration
C14: =Tekstnøgler!C76 -> Emissionsfaktor for flytransport | D14: =IF(ISBLANK(Hovedresultater!$E14),"",Hovedresultater!$E14) -> Inkluder RFI
C17: =Tekstnøgler!C325 -> Største CO₂e-udledning
C19: =Tekstnøgler!C583 -> På denne side kan du få indblik i, hvilke af dine indtastninger i Klimakompasset, der fylder mest i din virksomheds klimaregnskab – en såkaldt hot spot analyse. Med udpegning af din virksomheds 20 største kilder til udledninger får du et hurtigt overblik over potentielle reduktionsmuligheder, så du kan fokusere på de vigtigste steder først, og prioritere de reducerende tiltag, der har størst effekt i din virksomhed. I tabellen nederst på siden kan du se de 20 indtastninger med størst udledning, og hvor stor en procentdel de udgør af virksomhedens samlede udledninger i scope 1, 2 og 3.
C21: =Tekstnøgler!C584 -> Figur 1: CO₂e-udledning i ton scope 1, 2 og 3 fordelt på poster
C39: =Tekstnøgler!C328 -> OVERSIGT OVER UDLEDNINGEN I TON CO₂-E FORDELT PÅ POSTER
C40: =Tekstnøgler!C329 -> Beskrivelse | D40: =Tekstnøgler!C330 -> Placering | E40: =Tekstnøgler!C203 -> Scope 1 | F40: =Tekstnøgler!C204 -> Scope 2 | G40: =Tekstnøgler!C205 -> Scope 3 | H40: =Tekstnøgler!C580 -> Scope 1, 2 og 3 udledning | I40: =Tekstnøgler!C581 -> Procentdel af udledning i scope 1, 2 og 3
C41: =Tekstnøgler!C374&" > "&Tekstnøgler!C557&" > "&Tekstnøgler!C135 -> Indkøb > Materialer > Indkøb af materialer i fysiske enheder | D41: Træ | E41: 0 | F41: 0 | G41: 3311.8492 | H41: =SUM(E41:G41) -> 3311.8492 | I41: =IF(ISBLANK($H41),,$H41/Hovedresultater!$D$29) -> 0.32371967
C42: =Tekstnøgler!C374&" > "&Tekstnøgler!C557&" > "&Tekstnøgler!C135 -> Indkøb > Materialer > Indkøb af materialer i fysiske enheder | D42: Nyt glas | E42: 0 | F42: 0 | G42: 2500.133 | H42: =SUM(E42:G42) -> 2500.133 | I42: =IF(ISBLANK($H42),,$H42/Hovedresultater!$D$29) -> 0.24437774
C43: =Tekstnøgler!C373&" > "&Tekstnøgler!C553&" > "&Tekstnøgler!C122 -> Energi og processer > Elektricitet > Forbrug af elektricitet | D43: Elektricitet | E43: 0 | F43: 1851.795 | G43: 331.10115 | H43: =SUM(E43:G43) -> 2182.8961 | I43: =IF(ISBLANK($H43),,$H43/Hovedresultater!$D$29) -> 0.21336914
C44: =Tekstnøgler!C374&" > "&Tekstnøgler!C557&" > "&Tekstnøgler!C135 -> Indkøb > Materialer > Indkøb af materialer i fysiske enheder | D44: Stål | E44: 0 | F44: 0 | G44: 948.94802 | H44: =SUM(E44:G44) -> 948.94802 | I44: =IF(ISBLANK($H44),,$H44/Hovedresultater!$D$29) -> 0.092755775
C45: =Tekstnøgler!C375&" > "&Tekstnøgler!C566&" > "&Tekstnøgler!C176 -> Transport > Varetransport til kunde > Varetransport i fysiske enheder | D45: Varetransport til ku | E45: 0 | F45: 0 | G45: 546.56 | H45: =SUM(E45:G45) -> 546.56 | I45: =IF(ISBLANK($H45),,$H45/Hovedresultater!$D$29) -> 0.053423997
C46: =Tekstnøgler!C373&" > "&Tekstnøgler!C554&" > "&Tekstnøgler!C126 -> Energi og processer > Varme og procesenergi > Brændsler | D46: Varme | E46: 326.8582 | F46: 0 | G46: 52.287801 | H46: =SUM(E46:G46) -> 379.146 | I46: =IF(ISBLANK($H46),,$H46/Hovedresultater!$D$29) -> 0.037059966
C47: =Tekstnøgler!C375&" > "&Tekstnøgler!C565&" > "&Tekstnøgler!C172 -> Transport > Varetransport til virksomhed > Varetransport i fysiske enheder | D47: Transport til virk | E47: 0 | F47: 0 | G47: 204.96 | H47: =SUM(E47:G47) -> 204.96 | I47: =IF(ISBLANK($H47),,$H47/Hovedresultater!$D$29) -> 0.020033999
C48: =Tekstnøgler!C373&" > "&Tekstnøgler!C554&" > "&Tekstnøgler!C126 -> Energi og processer > Varme og procesenergi > Brændsler | D48: Benzin | E48: 108.58751 | F48: 0 | G48: 29.206461 | H48: =SUM(E48:G48) -> 137.79397 | I48: =IF(ISBLANK($H48),,$H48/Hovedresultater!$D$29) -> 0.013468795
C49: =Tekstnøgler!C375&" > "&Tekstnøgler!C563&" > "&Tekstnøgler!C163 -> Transport > Egne og leasede transportmidler > Egne og leasede transportmidler | D49: Kundemøder | E49: 7.9191354 | F49: 0 | G49: 2.1299865 | H49: =SUM(E49:G49) -> 10.049122 | I49: =IF(ISBLANK($H49),,$H49/Hovedresultater!$D$29) -> 0.00098226042
C50: =Tekstnøgler!C374&" > "&Tekstnøgler!C558&" > "&Tekstnøgler!C140 -> Indkøb > Produkter og services > Indkøb af produkter i fysiske enheder | D50: Vand | E50: 0 | F50: 0 | G50: 4.6554366 | H50: =SUM(E50:G50) -> 4.6554366 | I50: =IF(ISBLANK($H50),,$H50/Hovedresultater!$D$29) -> 0.00045504982
C51: =Tekstnøgler!C375&" > "&Tekstnøgler!C564&" > "&Tekstnøgler!C167 -> Transport > Medarbejdertransport > Pendling | D51: Pendling | E51: 0 | F51: 0 | G51: 3.6176839 | H51: =SUM(E51:G51) -> 3.6176839 | I51: =IF(ISBLANK($H51),,$H51/Hovedresultater!$D$29) -> 0.00035361375
C52: =Tekstnøgler!C376&" > "&Tekstnøgler!C568&" > "&Tekstnøgler!C182 -> Affald og genbrug > Affald > Affald | D52: Glas | E52: 0 | F52: 0 | G52: 0 | H52: =SUM(E52:G52) -> 0 | I52: =IF(ISBLANK($H52),,$H52/Hovedresultater!$D$29) -> 0
C53: =Tekstnøgler!C376&" > "&Tekstnøgler!C568&" > "&Tekstnøgler!C182 -> Affald og genbrug > Affald > Affald | D53: Stål | E53: 0 | F53: 0 | G53: 0 | H53: =SUM(E53:G53) -> 0 | I53: =IF(ISBLANK($H53),,$H53/Hovedresultater!$D$29) -> 0
C54: =Tekstnøgler!C376&" > "&Tekstnøgler!C568&" > "&Tekstnøgler!C182 -> Affald og genbrug > Affald > Affald | D54: Træ | E54: 0 | F54: 0 | G54: 0 | H54: =SUM(E54:G54) -> 0 | I54: =IF(ISBLANK($H54),,$H54/Hovedresultater!$D$29) -> 0
C55: =Tekstnøgler!C377&" > "&Tekstnøgler!C573&" > "&Tekstnøgler!C191 -> Solgte produkter > End-of-life behandling > Håndtering af affaldsprodukt | D55: Glas | E55: 0 | F55: 0 | G55: 0 | H55: =SUM(E55:G55) -> 0 | I55: =IF(ISBLANK($H55),,$H55/Hovedresultater!$D$29) -> 0
C56: =Tekstnøgler!C377&" > "&Tekstnøgler!C573&" > "&Tekstnøgler!C191 -> Solgte produkter > End-of-life behandling > Håndtering af affaldsprodukt | D56: Træ | E56: 0 | F56: 0 | G56: 0 | H56: =SUM(E56:G56) -> 0 | I56: =IF(ISBLANK($H56),,$H56/Hovedresultater!$D$29) -> 0
C57: =Tekstnøgler!C377&" > "&Tekstnøgler!C573&" > "&Tekstnøgler!C191 -> Solgte produkter > End-of-life behandling > Håndtering af affaldsprodukt | D57: Stål | E57: 0 | F57: 0 | G57: 0 | H57: =SUM(E57:G57) -> 0 | I57: =IF(ISBLANK($H57),,$H57/Hovedresultater!$D$29) -> 0
H58: =SUM(E58:G58) -> 0 | I58: =IF(ISBLANK($H58),,$H58/Hovedresultater!$D$29) -> 0
H59: =SUM(E59:G59) -> 0 | I59: =IF(ISBLANK($H59),,$H59/Hovedresultater!$D$29) -> 0
H60: =SUM(E60:G60) -> 0 | I60: =IF(ISBLANK($H60),,$H60/Hovedresultater!$D$29) -> 0
C61: =Tekstnøgler!C105 -> Ton CO₂e | E61: =SUM(E41:E60) -> 443.36484 | F61: =SUM(F41:F60) -> 1851.795 | G61: =SUM(G41:G60) -> 7935.4487 | H61: =SUM(H41:H60) -> 10230.609 | I61: =SUM(I41:I60) -> 1

Sheet Fremskrivning - Hovedresultater
C2: =Tekstnøgler!C335 -> Resultater for fremskrivning | H2: =Tekstnøgler!C2 -> <-- Gå til forsiden
C5: =Tekstnøgler!C336 -> Fremskrivning for
C7: =Tekstnøgler!C337 -> Basisberegning
C8: [TITEL]
C10: =Tekstnøgler!C339 -> Basisår | D10: =Tekstnøgler!C340 -> Slutår | E10: =Tekstnøgler!C588 -> Emissionsfaktorår
C11: 2015 | D11: 2030 | E11: =Emissionsfaktorer!B5 -> 2021
C13: =Tekstnøgler!C341 -> Valg af årlig vækst
C14: =Tekstnøgler!C342 -> Årlig vækstrate | D14: 0.03
C15: =Tekstnøgler!C343 -> Type af vækstrate | D15: Ekspotentiel
C18: =Tekstnøgler!C344 -> Hovedresultater
C20: =IF('Fremskrivning - Delresultater'!M28-'Fremskrivning - Delresultater'!H28>=0,Tekstnøgler!C386&'Fremskrivning - Hovedresultater'!D14*100&"% ("&'Fremskrivning - Hovedresultater'!D15&Tekstnøgler!C387&ROUND('Fremskrivning - Delresultater'!Z27*100,0)&Tekstnøgler!C389&'Fremskrivning - Hovedresultater'!D11&".",Tekstnøgler!C386&'Fremskrivning - Hovedresultater'!D14*100&"% ("&'Fremskrivning - Hovedresultater'!D15&Tekstnøgler!C388&ROUND('Fremskrivning - Delresultater'!Z26*100,0)&Tekstnøgler!C389&'Fremskrivning - Hovedresultater'!D11&".") -> Med en årlig vækst på 3% (Ekspotentiel) estimeres det, at din virksomheds CO₂e-udledninger vil falde med -50% frem mod år2030.
C22: =Tekstnøgler!C346 -> Tabel 1: Oversigt over virksomhedens CO₂e-udledninger fordelt på scopes
C23: =Tekstnøgler!C347 -> Titel | D23: =Tekstnøgler!C348 -> Ton CO₂e | F23: =Tekstnøgler!C349 -> Fordeling i %
D24: =$C$11 -> 2015 | E24: =$D$11 -> 2030 | F24: =$C$11 -> 2015 | G24: =$D$11 -> 2030
C25: =Tekstnøgler!C351 -> Scope 1 | D25: =LOOKUP($C$11,'Fremskrivning - Delresultater'!$D$15:$X$15,'Fremskrivning - Delresultater'!D16:X16) -> 11 | E25: =LOOKUP($D$11,'Fremskrivning - Delresultater'!$D$15:$X$15,'Fremskrivning - Delresultater'!D16:X16) -> 4 | F25: =IF($D$28 = 0,"",D25/$D$28) -> 0.42307692 | G25: =IF($E$28 = 0,"",E25/$E$28) -> 0.30769231
C26: =Tekstnøgler!C352 -> Scope 2 | D26: =LOOKUP($C$11,'Fremskrivning - Delresultater'!$D$15:$X$15,'Fremskrivning - Delresultater'!D17:X17) -> 7 | E26: =LOOKUP($D$11,'Fremskrivning - Delresultater'!$D$15:$X$15,'Fremskrivning - Delresultater'!D17:X17) -> 4 | F26: =IF($D$28 = 0,"",D26/$D$28) -> 0.26923077 | G26: =IF($E$28 = 0,"",E26/$E$28) -> 0.30769231
C27: =Tekstnøgler!C353 -> Scope 3 | D27: =LOOKUP($C$11,'Fremskrivning - Delresultater'!$D$15:$X$15,'Fremskrivning - Delresultater'!D18:X18) -> 8 | E27: =LOOKUP($D$11,'Fremskrivning - Delresultater'!$D$15:$X$15,'Fremskrivning - Delresultater'!D18:X18) -> 5 | F27: =IF($D$28 = 0,"",D27/$D$28) -> 0.30769231 | G27: =IF($E$28 = 0,"",E27/$E$28) -> 0.38461538
C28: =Tekstnøgler!C95 -> Total | D28: =SUM(D25:D27) -> 26 | E28: =SUM(E25:E27) -> 13 | F28: =SUM(F25:F27) -> 1 | G28: =SUM(G25:G27) -> 1
C29: =Tekstnøgler!C355 -> Udenfor scopes | D29: =LOOKUP($C$11,'Fremskrivning - Delresultater'!D117:X117,'Fremskrivning - Delresultater'!D193:X193) -> 8 | E29: =LOOKUP($D$11,'Fremskrivning - Delresultater'!D117:X117,'Fremskrivning - Delresultater'!D193:X193) -> 8
A30: Ny | C30: =IF(E25>D25,"Målsætning for scope 1 fratrukket reduktionen","Målsætning for scope 1") -> Målsætning for scope 1 | I30: =MIN(E25,D25) -> 4 | L30: Skjult række
A31: Ny | C31: =IF(D25>E25,Tekstnøgler!C356,Tekstnøgler!C359) -> Reduktion opnået (scope 1) | I31: =IF(-MIN(E25-D25,0)=0,"",-MIN(E25-D25,0)) -> 7 | L31: Skjult række
A32: Ny | C32: =IF(D25<=E25,Tekstnøgler!C358,Tekstnøgler!C359) -> (ikke relevant) | I32: =IF(MAX(E25-D25,0)=0,"",MAX(E25-D25,0)) | L32: Skjult række
A33: Ny | C33: =IF(E25>D25,"Målsætning for scope 1 fratrukket reduktionen (visning)","Målsætning for scope 1 (visning)") -> Målsætning for scope 1 (visning) | J33: =I30 -> 4 | L33: Skjult række
A34: Ny | C34: =IF(D25>E25,"Reduktion opnået for scope 1 (visning)","") -> Reduktion opnået for scope 1 (visning) | J34: =I31 -> 7 | L34: Skjult række
A35: Ny | C35: =IF(D25<=E25,"Forskel til målet for scope 1 (visning)","") | J35: =I32 | L35: Skjult række
A36: Ny | C36: Etikets værdi for scope 1 (reduktion) | J36: =IF(E25-D25<0,ROUND((E25-D25)/D25,3),"") -> -0.636 | L36: Skjult række
A37: Ny | C37: Etikets værdi for scope 1 (stigning) | J37: =IF(E25-D25>=0,ROUND((E25-D25)/D25,3),"") | L37: Skjult række
A38: Ny | L38: Skjult række
A39: Ny | D39: =$D$24 -> 2015 | E39: =$E$24 -> 2030 | L39: Skjult række
A40: Ny | C40: =$C$26 -> Scope 2 | D40: =$D26 -> 7 | E40: =$E26 -> 4 | L40: Skjult række
A41: Ny | C41: =IF(E26>D26,"Målsætning for scope 2 fratrukket reduktionen","Målsætning for scope 2") -> Målsætning for scope 2 | I41: =MIN(E26,D26) -> 4 | L41: Skjult række
A42: Ny | C42: =IF(D26>E26,Tekstnøgler!C360,Tekstnøgler!C363) -> Reduktion opnået (scope 2) | I42: =IF(-MIN(E26-D26,0)=0,"",-MIN(E26-D26,0)) -> 3 | L42: Skjult række
A43: Ny | C43: =IF(D26<=E26,Tekstnøgler!C362,Tekstnøgler!C363) -> (ikke relevant) | I43: =IF(MAX(E26-D26,0)=0,"",MAX(E26-D26,0)) | L43: Skjult række
A44: Ny | C44: =IF(E26>D26,"Målsætning for scope 2 fratrukket reduktionen (visning)","Målsætning for scope 2 (visning)") -> Målsætning for scope 2 (visning) | J44: =I41 -> 4 | L44: Skjult række
A45: Ny | C45: =IF(D26>E26,"Reduktion opnået for scope 2 (visning)","") -> Reduktion opnået for scope 2 (visning) | J45: =I42 -> 3 | L45: Skjult række
A46: Ny | C46: =IF(D26<=E26,"Stigning af scope 2 udledninger (visning)","") | J46: =I43 | L46: Skjult række
A47: Ny | C47: Etikets værdi for scope 2 (reduktion) | J47: =IF(E26-D26<0,ROUND((E26-D26)/D26,3),"") -> -0.429 | L47: Skjult række
A48: Ny | C48: Etikets værdi for scope 2 (stigning) | J48: =IF(E26-D26>=0,ROUND((E26-D26)/D26,3),"") | L48: Skjult række
A49: Ny | L49: Skjult række
A50: Ny | D50: =$D$24 -> 2015 | E50: =$E$24 -> 2030 | L50: Skjult række
...

Sheet Fremskrivning - Delresultater
C2: =Tekstnøgler!C392 -> Resultat | J2: =Tekstnøgler!C2 -> <-- Gå til forsiden
C5: =Tekstnøgler!C393 -> Delresultat for fremskrivning
C6: =Tekstnøgler!C394 -> Delresultat for fremskrivning
C10: =Tekstnøgler!C395 -> Delresultatet
C12: =Tekstnøgler!C396 -> Her ses en mere detaljeret resultatvisning for fremskrivning. Tabellen viser den tilhørende udledning i ton CO₂e for alle underkategorierne, som der er indtastet data for.
C13: =Tekstnøgler!C397 -> Tabel 1: Oversigt over virksomhedens CO₂e-udledninger fordelt på scopes
C14: =Tekstnøgler!C200 -> Scope | D14: =Tekstnøgler!C105 -> Ton CO₂e
D15: 2015 | E15: 2016 | F15: 2017 | G15: 2018 | H15: 2019 | I15: 2020 | J15: 2021 | K15: 2022 | L15: 2023 | M15: 2024 | N15: 2025 | O15: 2026 | P15: 2027 | Q15: 2028 | R15: 2029 | S15: 2030 | T15: 2031 | U15: 2032 | V15: 2033 | W15: 2034 | X15: 2035
C16: =Tekstnøgler!C203 -> Scope 1 | D16: =D109 -> 11 | E16: =H109 -> 8 | F16: =L109 -> 8 | G16: =P109 -> 8 | H16: =T109 -> 8 | I16: =X109 -> 8 | J16: =AB109 -> 8 | K16: =AF109 -> 8 | L16: =AJ109 -> 8 | M16: =AN109 -> 8 | N16: =AR109 -> 8 | O16: =AV109 -> 8 | P16: =AZ109 -> 8 | Q16: =BD109 -> 8 | R16: =BH109 -> 8 | S16: =BL109 -> 4 | T16: =BP109 -> 8 | U16: =BT109 -> 8 | V16: =BX109 -> 8 | W16: =CB109 -> 8 | X16: =CF109 -> 8
C17: =Tekstnøgler!C204 -> Scope 2 | D17: =E109 -> 7 | E17: =I109 -> 8 | F17: =M109 -> 8 | G17: =Q109 -> 8 | H17: =U109 -> 8 | I17: =Y109 -> 20 | J17: =AC109 -> 8 | K17: =AG109 -> 8 | L17: =AK109 -> 8 | M17: =AO109 -> 8 | N17: =AS109 -> 8 | O17: =AW109 -> 8 | P17: =BA109 -> 8 | Q17: =BE109 -> 8 | R17: =BI109 -> 21 | S17: =BM109 -> 4 | T17: =BQ109 -> 8 | U17: =BU109 -> 8 | V17: =BY109 -> 8 | W17: =CC109 -> 8 | X17: =CG109 -> 8
C18: =Tekstnøgler!C205 -> Scope 3 | D18: =F109 -> 8 | E18: =J109 -> 8 | F18: =N109 -> 8 | G18: =R109 -> 8 | H18: =V109 -> 8 | I18: =Z109 -> 8 | J18: =AD109 -> 8 | K18: =AH109 -> 8 | L18: =AL109 -> 8 | M18: =AP109 -> 8 | N18: =AT109 -> 8 | O18: =AX109 -> 8 | P18: =BB109 -> 8 | Q18: =BF109 -> 20 | R18: =BJ109 -> 8 | S18: =BN109 -> 5 | T18: =BR109 -> 8 | U18: =BV109 -> 8 | V18: =BZ109 -> 8 | W18: =CD109 -> 8 | X18: =CH109 -> 8
C19: =Tekstnøgler!C402 -> Total | D19: =SUM(D16:D18) -> 26 | E19: =SUM(E16:E18) -> 24 | F19: =SUM(F16:F18) -> 24 | G19: =SUM(G16:G18) -> 24 | H19: =SUM(H16:H18) -> 24 | I19: =SUM(I16:I18) -> 36 | J19: =SUM(J16:J18) -> 24 | K19: =SUM(K16:K18) -> 24 | ... X19: =SUM(X16:X18) -> 24
A20: Ny | C20: =IF(M28>H28,"Scopes 1+2+3 i basis år","Scopes 1+2+3 i målår") -> Scopes 1+2+3 i målår | Y20: =MIN(M28,H28) -> 13 | AA20: Skjult rækker
A21: Ny | C21: =IF(M28<H28,Tekstnøgler!C403,Tekstnøgler!C404) -> Reduktion opnået (scope 1+2+3) | Y21: =-MIN(M28-H28,0) -> 13 | AA21: Skjult rækker
A22: Ny | C22: =IF(M28>=H28,Tekstnøgler!C405,Tekstnøgler!C406) -> (ikke relevant) | Y22: =MAX(M28-H28,0) -> 0 | AA22: Skjult rækker
A23: Ny | C23: =IF(M28>H28,"Scopes 1+2+3 i basis år (visning)","Scopes 1+2+3 i målår (visning)") -> Scopes 1+2+3 i målår (visning) | Z23: =Y20 -> 13 | AA23: Skjult rækker
A24: Ny | C24: =IF(M28<H28,"Reduktion opnået for alle scopes (visning)","") -> Reduktion opnået for alle scopes (visning) | Z24: =Y21 -> 13 | AA24: Skjult rækker
A25: Ny | C25: =IF(M28>=H28,"Manglende reduktion for alle scopes (visning)","") | Z25: =Y22 -> 0 | AA25: Skjult rækker
A26: Ny | C26: Etikets værdi for scope 1+2+3 (reduktion) | Z26: =IF(M28-H28<0,ROUND((M28-H28)/H28,3),"") -> -0.5 | AA26: Skjult rækker
A27: Ny | C27: Etikets værdi for scope 1+2+3 (stigning) | Z27: =IF(M28-H28>=0,ROUND((M28-H28)/H28,3),"") | AA27: Skjult rækker
A28: Ny | E28: Scope 1+2+3 for basisår: | H28: =LOOKUP('Fremskrivning - Hovedresultater'!C11,'Fremskrivning - Delresultater'!D15:X15,'Fremskrivning - Delresultater'!D19:X19) -> 26 | J28: Scope 1+2+3 for slutår: | M28: =LOOKUP('Fremskrivning - Hovedresultater'!D11,'Fremskrivning - Delresultater'!D15:X15,'Fremskrivning - Delresultater'!D19:X19) -> 13 | AA28: Skjult rækker
C31: =Tekstnøgler!C408 -> Tabel 2. Oversigt over CO₂e-udledningen fordelt på hoved- og underkategorier
C32: År | D32: 2015 | H32: 2016 | L32: 2017 | P32: 2018 | T32: 2019 | X32: 2020 | AB32: 2021 | AF32: 2022 | AJ32: 2023 | AN32: 2024 | AR32: 2025 | AV32: 2026 | AZ32: 2027 | BD32: 2028 | BH32: 2029 | BL32: 2030 | BP32: 2031 | BT32: 2032 | BX32: 2033 | CB32: 2034 | CF32: 2035
C33: =Tekstnøgler!C115 -> Hovedkategori | D33: =Tekstnøgler!$C$409 -> Scope 1 - faktor | E33: =Tekstnøgler!$C$410 -> Scope 2 - faktor | F33: =Tekstnøgler!$C$411 -> Scope 3 - faktor | G33: =Tekstnøgler!$C$412 -> Samlede CO₂e udledning | H33: =Tekstnøgler!$C$409 -> Scope 1 - faktor | I33: =Tekstnøgler!$C$410 -> Scope 2 - faktor | J33: =Tekstnøgler!$C$411 -> Scope 3 - faktor | K33: =Tekstnøgler!$C$412 -> Samlede CO₂e udledning | L33: =Tekstnøgler!$C$409 -> Scope 1 - faktor | M33: =Tekstnøgler!$C$410 -> Scope 2 - faktor | N33: =Tekstnøgler!$C$411 -> Scope 3 - faktor | O33: =Tekstnøgler!$C$412 -> Samlede CO₂e udledning | P33: =Tekstnøgler!$C$409 -> Scope 1 - faktor | Q33: =Tekstnøgler!$C$410 -> Scope 2 - faktor | R33: =Tekstnøgler!$C$411 -> Scope 3 - faktor | S33: =Tekstnøgler!$C$412 -> Samlede CO₂e udledning | T33: =Tekstnøgler!$C$409 -> Scope 1 - faktor | U33: =Tekstnøgler!$C$410 -> Scope 2 - faktor | V33: =Tekstnøgler!$C$411 -> Scope 3 - faktor | W33: =Tekstnøgler!$C$412 -> Samlede CO₂e udledning | X33: =Tekstnøgler!$C$409 -> Scope 1 - faktor | Y33: =Tekstnøgler!$C$410 -> Scope 2 - faktor | Z33: =Tekstnøgler!$C$411 -> Scope 3 - faktor | AA33: =Tekstnøgler!$C$412 -> Samlede CO₂e udledning | AB33: =Tekstnøgler!$C$409 -> Scope 1 - faktor | AC33: =Tekstnøgler!$C$410 -> Scope 2 - faktor | AD33: =Tekstnøgler!$C$411 -> Scope 3 - faktor | AE33: =Tekstnøgler!$C$412 -> Samlede CO₂e udledning | AF33: =Tekstnøgler!$C$409 -> Scope 1 - faktor | AG33: =Tekstnøgler!$C$410 -> Scope 2 - faktor | AH33: =Tekstnøgler!$C$411 -> Scope 3 - faktor | AI33: =Tekstnøgler!$C$412 -> Samlede CO₂e udledning | AJ33: =Tekstnøgler!$C$409 -> Scope 1 - faktor | AK33: =Tekstnøgler!$C$410 -> Scope 2 - faktor | AL33: =Tekstnøgler!$C$411 -> Scope 3 - faktor | AM33: =Tekstnøgler!$C$412 -> Samlede CO₂e udledning | AN33: =Tekstnøgler!$C$409 -> Scope 1 - faktor | AO33: =Tekstnøgler!$C$410 -> Scope 2 - faktor | AP33: =Tekstnøgler!$C$411 -> Scope 3 - faktor | AQ33: =Tekstnøgler!$C$412 -> Samlede CO₂e udledning | AR33: =Tekstnøgler!$C$409 -> Scope 1 - faktor | AS33: =Tekstnøgler!$C$410 -> Scope 2 - faktor | AT33: =Tekstnøgler!$C$411 -> Scope 3 - faktor | AU33: =Tekstnøgler!$C$412 -> Samlede CO₂e udledning | AV33: =Tekstnøgler!$C$409 -> Scope 1 - faktor | AW33: =Tekstnøgler!$C$410 -> Scope 2 - faktor | AX33: =Tekstnøgler!$C$411 -> Scope 3 - faktor | AY33: =Tekstnøgler!$C$412 -> Samlede CO₂e udledning | AZ33: =Tekstnøgler!$C$409 -> Scope 1 - faktor | BA33: =Tekstnøgler!$C$410 -> Scope 2 - faktor | BB33: =Tekstnøgler!$C$411 -> Scope 3 - faktor | BC33: =Tekstnøgler!$C$412 -> Samlede CO₂e udledning | BD33: =Tekstnøgler!$C$409 -> Scope 1 - faktor | BE33: =Tekstnøgler!$C$410 -> Scope 2 - faktor | BF33: =Tekstnøgler!$C$411 -> Scope 3 - faktor | BG33: =Tekstnøgler!$C$412 -> Samlede CO₂e udledning | BH33: =Tekstnøgler!$C$409 -> Scope 1 - faktor | BI33: =Tekstnøgler!$C$410 -> Scope 2 - faktor | BJ33: =Tekstnøgler!$C$411 -> Scope 3 - faktor | BK33: =Tekstnøgler!$C$412 -> Samlede CO₂e udledning | BL33: =Tekstnøgler!$C$409 -> Scope 1 - faktor | BM33: =Tekstnøgler!$C$410 -> Scope 2 - faktor | BN33: =Tekstnøgler!$C$411 -> Scope 3 - faktor | BO33: =Tekstnøgler!$C$412 -> Samlede CO₂e udledning | BP33: =Tekstnøgler!$C$409 -> Scope 1 - faktor | BQ33: =Tekstnøgler!$C$410 -> Scope 2 - faktor | BR33: =Tekstnøgler!$C$411 -> Scope 3 - faktor | BS33: =Tekstnøgler!$C$412 -> Samlede CO₂e udledning | BT33: =Tekstnøgler!$C$409 -> Scope 1 - faktor | BU33: =Tekstnøgler!$C$410 -> Scope 2 - faktor | BV33: =Tekstnøgler!$C$411 -> Scope 3 - faktor | BW33: =Tekstnøgler!$C$412 -> Samlede CO₂e udledning | BX33: =Tekstnøgler!$C$409 -> Scope 1 - faktor | BY33: =Tekstnøgler!$C$410 -> Scope 2 - faktor | BZ33: =Tekstnøgler!$C$411 -> Scope 3 - faktor | CA33: =Tekstnøgler!$C$412 -> Samlede CO₂e udledning | CB33: =Tekstnøgler!$C$409 -> Scope 1 - faktor | CC33: =Tekstnøgler!$C$410 -> Scope 2 - faktor | CD33: =Tekstnøgler!$C$411 -> Scope 3 - faktor | CE33: =Tekstnøgler!$C$412 -> Samlede CO₂e udledning | CF33: =Tekstnøgler!$C$409 -> Scope 1 - faktor | CG33: =Tekstnøgler!$C$410 -> Scope 2 - faktor | CH33: =Tekstnøgler!$C$411 -> Scope 3 - faktor | CI33: =Tekstnøgler!$C$412 -> Samlede CO₂e udledning
D34: =Tekstnøgler!$C$413 -> (ton CO₂e) | E34: =Tekstnøgler!$C$413 -> (ton CO₂e) | F34: =Tekstnøgler!$C$413 -> (ton CO₂e) | G34: =Tekstnøgler!$C$413 -> (ton CO₂e) | H34: =Tekstnøgler!$C$413 -> (ton CO₂e) | I34: =Tekstnøgler!$C$413 -> (ton CO₂e) | J34: =Tekstnøgler!$C$413 -> (ton CO₂e) | K34: =Tekstnøgler!$C$413 -> (ton CO₂e) | ... CI34: =Tekstnøgler!$C$413 -> (ton CO₂e)
